<?xml version="1.0"?>
<robot name="box_base">
    <link name="robot_base">
        <visual name="box_base5">
            <origin xyz="0.000235 -0.000001 -0.175002" rpy="0.000024 3.141593 -1.570796" />
            <geometry>
                <box size="0.250000 0.150000 0.010000" />
            </geometry>
            <material name="robot_base_material">
                <color rgba="0.850000 0.850000 1.000000 1.0" />
            </material>
        </visual>
        <visual name="box_base4">
            <origin xyz="-0.074754 0.000001 0.000002" rpy="-1.570804 3.141593 -1.570796" />
            <geometry>
                <box size="0.250000 0.350000 0.001000" />
            </geometry>
            <material name="robot_base_material">
                <color rgba="0.850000 0.850000 1.000000 1.0" />
            </material>
        </visual>
        <visual name="box_base3">
            <origin xyz="0.000254 0.124999 0.000005" rpy="-1.570796 3.141585 0.000017" />
            <geometry>
                <box size="0.150000 0.350000 0.010000" />
            </geometry>
            <material name="robot_base_material">
                <color rgba="0.850000 0.850000 1.000000 1.0" />
            </material>
        </visual>
        <visual name="box_base2">
            <origin xyz="0.000246 -0.124999 0.000002" rpy="-1.570796 3.141585 0.000026" />
            <geometry>
                <box size="0.150000 0.350000 0.010000" />
            </geometry>
            <material name="robot_base_material">
                <color rgba="0.850000 0.850000 1.000000 1.0" />
            </material>
        </visual>
        <visual name="box_base">
            <origin xyz="0.000245 0.000001 0.175002" rpy="0.000018 3.141593 -1.570796" />
            <geometry>
                <box size="0.250000 0.150000 0.010000" />
            </geometry>
            <material name="robot_base_material">
                <color rgba="0.850000 0.850000 1.000000 1.0" />
            </material>
        </visual>
    </link>
    <joint name="box_joint" type="revolute">
        <axis xyz="0 0 1" />
        <limit lower="-0.25307273864746" upper="2.3649210929871" velocity="6.2831854820251" effort="10.0" />
        <parent link="robot_base" />
        <child link="box_lid" />
        <origin xyz="0.076229 -0.123002 0.000020" rpy="0.000031 3.141592 -1.570803" />
    </joint>
    <link name="box_lid">
        <inertial>
            <origin rpy="1.570772 3.141586 -2.879811" xyz="0.126009 0.038258 -0.000070" />
            <inertia ixx="0.0095832388144441" iyz="-1.4173272439678e-10" izz="0.015189634999142" iyy="0.0056220551158996" ixz="4.1934084209953e-11" ixy="5.7642736313618e-13" />
            <mass value="0.93799996376038" />
        </inertial>
        <collision name="box_lid">
            <origin xyz="0.126009 0.038258 -0.000070" rpy="1.570772 3.141586 -2.879811" />
            <geometry>
                <box size="0.268000 0.350000 0.010000" />
            </geometry>
        </collision>
        <visual name="box_lid">
            <origin xyz="0.126009 0.038258 -0.000070" rpy="1.570772 3.141586 -2.879811" />
            <geometry>
                <box size="0.268000 0.350000 0.010000" />
            </geometry>
            <material name="box_lid_material">
                <color rgba="0.850000 0.850000 1.000000 1.0" />
            </material>
        </visual>
    </link>
</robot>
